<?xml version="1.0"?>
<robot name="RTCRobot">
  <!--Color define-->
  <material name="blue">
    <color rgba="0 0,8 0,8 1"/>
  </material>

  <material name="white">
    <color rgba="1 1 1 1"/>
  </material>

  <material name="black">
    <color rgba="0,066 0,066 0,066 1"/>
  </material>

  <!--Link define-->
  <link name="base_link">
    <visual>
      <origin rpy="1,5708 0 0" xyz="-0,5 0,77 -0,16"/>
      <geometry>
        <mesh filename="package://rtcrobot/model/agv18.STL" scale="0,001 0,001 0,001"/>
      </geometry>
      <material name="blue"/>
    </visual>
  </link>
  
  <link name="wheel_left">
  </link>
  
  <link name="wheel_right">
  </link>

  <link name="laser_frame">
    <visual>
      <origin rpy="1,5708 0 0" xyz="0,005 0,075 -0,03"/>
      <geometry>
        <mesh filename="package://rtcrobot/model/rplidar.stl" scale="0,001 0,001 0,001"/>
      </geometry>
      <material name="black"/>
    </visual>
  </link>

   <link name="base_footprint">
  </link>
  <link name="odom">
  </link>
  <link name="map">
  </link>
  <link name="imu_link">
  </link>

  <link name="camera_link">
  </link>

  <link name="depth_link">
  </link>

  <link name="sickscan1_link">
  </link>
  <link name="sickscan2_link">
  </link>
  
  <!--Joint define-->
  <joint name="base_to_wheel_left" type="fixed">
    <parent link="base_link"/>
    <child link="wheel_left"/>
    <origin xyz="0 -0.19 -0.06"/>
  </joint>
  
  <joint name="base_to_wheel_right" type="fixed">
    <parent link="base_link"/>
    <child link="wheel_right"/>
    <origin xyz="0 0.19 -0.06"/>
  </joint>

  <joint name="base_to_scanner" type="fixed">
    <parent link="base_link"/>
    <child link="laser_frame"/>
    <origin xyz="0 0 0.18" rpy="0.0 0.0 3.1416"/>
  </joint>

  <joint name="base_to_imu" type="fixed">
    <parent link="base_link"/>
    <child link="imu_link"/>
    <origin xyz="0.36 0 0.1" rpy="0.0 0.0 0"/>
  </joint>

  <joint name="base_to_camera" type="fixed">
    <parent link="base_link"/>
    <child link="camera_link"/>
    <origin xyz="0.36 0 0.10" rpy="0 0 0"/>
  </joint>

  <joint name="base_to_depth" type="fixed">
    <parent link="base_link"/>
    <child link="depth_link"/>
    <origin xyz="0.36 0 0.10" rpy="0 0 0"/>
  </joint>

  <joint name="base_to_sick1" type="fixed">
    <parent link="base_link"/>
    <child link="sickscan1_link"/>
    <origin xyz="0.34 0.20 0" rpy="3.1416 0 0.785398163"/>
  </joint>

  <joint name="base_to_sick2" type="fixed">
    <parent link="base_link"/>
    <child link="sickscan2_link"/>
    <origin xyz="-0.34 -0.20 0" rpy="3.1416 0 -2.35619449"/>
  </joint>
  
  <joint name="footprint_to_base" type="fixed">
    <parent link="base_footprint"/>
    <child link="base_link"/>
    <origin xyz="0 0 0.16"/>
  </joint>
  

  <joint name="map_to_odom" type="fixed">
    <parent link="map"/>
    <child link="odom"/>
    <origin xyz="0 0 0"/>
  </joint>
  
  <joint name="odom_to_base_footprint" type="floating">
    <parent link="odom"/>
    <child link="base_footprint"/>
    <origin xyz="0 0 0"/>
  </joint>
  
</robot>
